<?xml version="1.0" encoding="utf-8"?>
<!-- This URDF was automatically created by SolidWorks to URDF Exporter! Originally created by Stephen Brawner (brawner@gmail.com) 
     Commit Version: 1.6.0-4-g7f85cfe  Build Version: 1.6.7995.38578
     For more information, please see http://wiki.ros.org/sw_urdf_exporter -->
<robot
  name="CORE">
  <link
    name="core_link">
    <inertial>
      <origin
        xyz="-0.000112694532404038 1.24521905287001E-09 -0.0331408855147186"
        rpy="0 0 0" />
      <mass
        value="0.604030648605638" />
      <inertia
        ixx="0.000362368952537499"
        ixy="3.69223885173125E-11"
        ixz="-6.05179883796121E-11"
        iyy="0.000225086967995155"
        iyz="-6.86866398187668E-12"
        izz="0.000407084552559391" />
    </inertial>
    <visual>
      <origin
        xyz="0 0 0"
        rpy="0 0 0" />
      <geometry>
        <mesh
          filename="package://CORE/meshes/core_link.STL" />
      </geometry>
      <material
        name="">
        <color
          rgba="0.564705882352941 0.564705882352941 0.564705882352941 1" />
      </material>
    </visual>
    <collision>
      <origin
        xyz="0 0 0"
        rpy="0 0 0" />
      <geometry>
        <mesh
          filename="package://CORE/meshes/core_link.STL" />
      </geometry>
    </collision>
  </link>
  <link
    name="wheel_1">
    <inertial>
      <origin
        xyz="-0.01248 -2.5517E-08 -1.6458E-05"
        rpy="0 0 0" />
      <mass
        value="0.096925" />
      <inertia
        ixx="4.4379E-05"
        ixy="5.581E-13"
        ixz="-2.3462E-13"
        iyy="2.2503E-05"
        iyz="1.4393E-14"
        izz="2.2504E-05" />
    </inertial>
    <visual>
      <origin
        xyz="0 0 0"
        rpy="0 0 0" />
      <geometry>
        <mesh
          filename="package://CORE/meshes/wheel_1.STL" />
      </geometry>
      <material
        name="">
        <color
          rgba="0.28235 0.28235 0.28235 1" />
      </material>
    </visual>
    <collision>
      <origin
        xyz="0 0 0"
        rpy="0 0 0" />
      <geometry>
        <mesh
          filename="package://CORE/meshes/wheel_1.STL" />
      </geometry>
    </collision>
  </link>
  <joint
    name="wheel_1"
    type="continuous">
    <origin
      xyz="0.132 0 -0.0445"
      rpy="0 0 0" />
    <parent
      link="core_link" />
    <child
      link="wheel_1" />
    <axis
      xyz="-1 0 0" />
    <limit
      effort="10"
      velocity="10" />
    <dynamics
      damping="0.1"
      friction="0.1" />
  </joint>
  <link
    name="wheel_2">
    <inertial>
      <origin
        xyz="2.55166618962771E-08 1.64579697312442E-05 -0.0124800368672634"
        rpy="0 0 0" />
      <mass
        value="0.096924875888147" />
      <inertia
        ixx="2.25033220760335E-05"
        ixy="1.43930301576104E-14"
        ixz="-5.58103400211959E-13"
        iyy="2.25037475309425E-05"
        iyz="2.34618173825359E-13"
        izz="4.43791952630414E-05" />
    </inertial>
    <visual>
      <origin
        xyz="0 0 0"
        rpy="0 0 0" />
      <geometry>
        <mesh
          filename="package://CORE/meshes/wheel_2.STL" />
      </geometry>
      <material
        name="">
        <color
          rgba="1 1 1 1" />
      </material>
    </visual>
    <collision>
      <origin
        xyz="0 0 0"
        rpy="0 0 0" />
      <geometry>
        <mesh
          filename="package://CORE/meshes/wheel_2.STL" />
      </geometry>
    </collision>
  </link>
  <joint
    name="wheel_2"
    type="continuous">
    <origin
      xyz="0 0.132 -0.0445"
      rpy="-1.5708 0 0" />
    <parent
      link="core_link" />
    <child
      link="wheel_2" />
    <axis
      xyz="0 0 -1" />
    <limit
      effort="10"
      velocity="10" />
    <dynamics
      damping="0.1"
      friction="0.1" />
  </joint>
  <link
    name="wheel_3">
    <inertial>
      <origin
        xyz="0.0124800368672635 2.55166619639313E-08 -1.64579697313205E-05"
        rpy="0 0 0" />
      <mass
        value="0.0969248758881469" />
      <inertia
        ixx="4.43791952630414E-05"
        ixy="5.581034009113E-13"
        ixz="2.34618173175042E-13"
        iyy="2.25033220760335E-05"
        iyz="-1.43930292819358E-14"
        izz="2.25037475309425E-05" />
    </inertial>
    <visual>
      <origin
        xyz="0 0 0"
        rpy="0 0 0" />
      <geometry>
        <mesh
          filename="package://CORE/meshes/wheel_3.STL" />
      </geometry>
      <material
        name="">
        <color
          rgba="0.282352941176471 0.282352941176471 0.282352941176471 1" />
      </material>
    </visual>
    <collision>
      <origin
        xyz="0 0 0"
        rpy="0 0 0" />
      <geometry>
        <mesh
          filename="package://CORE/meshes/wheel_3.STL" />
      </geometry>
    </collision>
  </link>
  <joint
    name="wheel_3"
    type="continuous">
    <origin
      xyz="-0.132 0 -0.0445"
      rpy="0 0 0" />
    <parent
      link="core_link" />
    <child
      link="wheel_3" />
    <axis
      xyz="1 0 0" />
    <limit
      effort="10"
      velocity="10" />
    <dynamics
      damping="0.1"
      friction="0.1" />
  </joint>
  <link
    name="wheel_4">
    <inertial>
      <origin
        xyz="-2.55166619413799E-08 1.64579697312581E-05 0.0124800368672635"
        rpy="0 0 0" />
      <mass
        value="0.0969248758881472" />
      <inertia
        ixx="2.25033220760335E-05"
        ixy="-1.43930300309017E-14"
        ixz="-5.58103400694971E-13"
        iyy="2.25037475309425E-05"
        iyz="-2.34618195315646E-13"
        izz="4.43791952630414E-05" />
    </inertial>
    <visual>
      <origin
        xyz="0 0 0"
        rpy="0 0 0" />
      <geometry>
        <mesh
          filename="package://CORE/meshes/wheel_4.STL" />
      </geometry>
      <material
        name="">
        <color
          rgba="0.282352941176471 0.282352941176471 0.282352941176471 1" />
      </material>
    </visual>
    <collision>
      <origin
        xyz="0 0 0"
        rpy="0 0 0" />
      <geometry>
        <mesh
          filename="package://CORE/meshes/wheel_4.STL" />
      </geometry>
    </collision>
  </link>
  <joint
    name="wheel_4"
    type="continuous">
    <origin
      xyz="0 -0.132 -0.0445"
      rpy="-1.5708 0 0" />
    <parent
      link="core_link" />
    <child
      link="wheel_4" />
    <axis
      xyz="0 0 1" />
    <limit
      effort="10"
      velocity="10" />
    <dynamics
      damping="0.1"
      friction="0.1" />
  </joint>
</robot>